<?xml version="1.0" ?>
<robot name="dummy-ros2" xmlns:xacro="http://www.ros.org/wiki/xacro">

<xacro:include filename="$(find dummy-ros2_description)/urdf/materials.xacro" />
<xacro:include filename="$(find realsense2_description)/urdf/_d435.urdf.xacro" />

<!-- 基础连接：世界 -> base_link -->
<link name="world" />

<joint name="world_joint" type="fixed">
  <parent link="world" />
  <child link="base_link" />
  <origin xyz="0.0 0.0 0.0" rpy="3.1415926536 3.1415926536 0.0" />
</joint>

<!-- 基座链接 -->
<link name="base_link">
  <inertial>
    <origin xyz="-0.015 -0.082 0.033" rpy="0 0 0"/>
    <mass value="2.718"/>
    <inertia ixx="0.005512" iyy="0.005791" izz="0.005729" ixy="0.0" iyz="0.0" ixz="0.0"/>
  </inertial>
  <visual>
    <origin xyz="0 0 0" rpy="0 0 0"/>
    <geometry>
      <mesh filename="file://$(find dummy-ros2_description)/meshes/base_link.stl" scale="0.001 0.001 0.001"/>
    </geometry>
    <material name="silver"/>
  </visual>
  <collision>
    <origin xyz="0 0 0" rpy="0 0 0"/>
    <geometry>
      <mesh filename="file://$(find dummy-ros2_description)/meshes/base_link.stl" scale="0.001 0.001 0.001"/>
    </geometry>
  </collision>
</link>

<!-- 第一个关节链接 -->
<link name="link1_1_1">
  <inertial>
    <origin xyz="-0.010 -0.010 0.017" rpy="0 0 0"/>
    <mass value="0.417"/>
    <inertia ixx="0.00024" iyy="0.000197" izz="0.000294" ixy="0.0" iyz="0.0" ixz="0.0"/>
  </inertial>
  <visual>
    <origin xyz="0.015 0.079017 -0.0825" rpy="0 0 0"/>
    <geometry>
      <mesh filename="file://$(find dummy-ros2_description)/meshes/link1_1_1.stl" scale="0.001 0.001 0.001"/>
    </geometry>
    <material name="silver"/>
  </visual>
  <collision>
    <origin xyz="0.015 0.079017 -0.0825" rpy="0 0 0"/>
    <geometry>
      <mesh filename="file://$(find dummy-ros2_description)/meshes/link1_1_1.stl" scale="0.001 0.001 0.001"/>
    </geometry>
  </collision>
</link>

<!-- 第二个关节链接 -->
<link name="link2_1_1">
  <inertial>
    <origin xyz="0.016 0.0 0.074" rpy="0 0 0"/>
    <mass value="0.825"/>
    <inertia ixx="0.003112" iyy="0.003172" izz="0.000413" ixy="0.0" iyz="0.0" ixz="0.0"/>
  </inertial>
  <visual>
    <origin xyz="0.032 0.114017 -0.12" rpy="0 0 0"/>
    <geometry>
      <mesh filename="file://$(find dummy-ros2_description)/meshes/link2_1_1.stl" scale="0.001 0.001 0.001"/>
    </geometry>
    <material name="silver"/>
  </visual>
  <collision>
    <origin xyz="0.032 0.114017 -0.12" rpy="0 0 0"/>
    <geometry>
      <mesh filename="file://$(find dummy-ros2_description)/meshes/link2_1_1.stl" scale="0.001 0.001 0.001"/>
    </geometry>
  </collision>
</link>

<!-- 第三个关节链接 -->
<link name="link3_1_1">
  <inertial>
    <origin xyz="-0.006 0.0 0.033" rpy="0 0 0"/>
    <mass value="0.334"/>
    <inertia ixx="0.000242" iyy="0.000299" izz="0.000122" ixy="0.0" iyz="0.0" ixz="0.0"/>
  </inertial>
  <visual>
    <origin xyz="-0.0 0.114017 -0.266" rpy="0 0 0"/>
    <geometry>
      <mesh filename="file://$(find dummy-ros2_description)/meshes/link3_1_1.stl" scale="0.001 0.001 0.001"/>
    </geometry>
    <material name="silver"/>
  </visual>
  <collision>
    <origin xyz="-0.0 0.114017 -0.266" rpy="0 0 0"/>
    <geometry>
      <mesh filename="file://$(find dummy-ros2_description)/meshes/link3_1_1.stl" scale="0.001 0.001 0.001"/>
    </geometry>
  </collision>
</link>

<!-- 第四个关节链接 -->
<link name="link4_1_1">
  <inertial>
    <origin xyz="0.005 -0.059 0.0" rpy="0 0 0"/>
    <mass value="0.382"/>
    <inertia ixx="0.000681" iyy="0.000077" izz="0.000663" ixy="0.0" iyz="0.0" ixz="0.0"/>
  </inertial>
  <visual>
    <origin xyz="0.017 0.131517 -0.318" rpy="0 0 0"/>
    <geometry>
      <mesh filename="file://$(find dummy-ros2_description)/meshes/link4_1_1.stl" scale="0.001 0.001 0.001"/>
    </geometry>
    <material name="silver"/>
  </visual>
  <collision>
    <origin xyz="0.017 0.131517 -0.318" rpy="0 0 0"/>
    <geometry>
      <mesh filename="file://$(find dummy-ros2_description)/meshes/link4_1_1.stl" scale="0.001 0.001 0.001"/>
    </geometry>
  </collision>
</link>

<!-- 第五个关节链接 -->
<link name="link5_1_1">
  <inertial>
    <origin xyz="0.001 -0.029 0.0" rpy="0 0 0"/>
    <mass value="0.141"/>
    <inertia ixx="0.000118" iyy="0.000036" izz="0.000122" ixy="0.0" iyz="0.0" ixz="0.0"/>
  </inertial>
  <visual>
    <origin xyz="-0.01 -0.08 -0.318" rpy="0 0 0"/>
    <geometry>
      <mesh filename="file://$(find dummy-ros2_description)/meshes/link5_1_1.stl" scale="0.001 0.001 0.001"/>
    </geometry>
    <material name="silver"/>
  </visual>
  <collision>
    <origin xyz="-0.01 -0.08 -0.318" rpy="0 0 0"/>
    <geometry>
      <mesh filename="file://$(find dummy-ros2_description)/meshes/link5_1_1.stl" scale="0.001 0.001 0.001"/>
    </geometry>
  </collision>
</link>

<!-- 第六个关节链接 -->
<link name="link6_1_1">
  <inertial>
    <origin xyz="0.0 0.010 0.0" rpy="0 0 0"/>
    <mass value="0.216"/>
    <inertia ixx="0.000031" iyy="0.000042" izz="0.000032" ixy="0.0" iyz="0.0" ixz="0.0"/>
  </inertial>
  <visual>
    <origin xyz="0.013 0.2465 -0.3545" rpy="0 0 3.141592654"/>
    <geometry>
      <mesh filename="file://$(find dummy-ros2_description)/meshes/link6_1_1.stl" scale="0.001 0.001 0.001"/>
    </geometry>
    <material name="silver"/>
  </visual>
  <collision>
    <origin xyz="0.013 0.2465 -0.3545" rpy="0 0 3.141592654"/>
    <geometry>
      <mesh filename="file://$(find dummy-ros2_description)/meshes/link6_1_1.stl" scale="0.001 0.001 0.001"/>
    </geometry>
  </collision>
</link>

<!-- 关节定义 - 添加阻尼和摩擦力 -->
<joint name="joint1" type="revolute">
  <origin xyz="-0.015 -0.079017 0.0825" rpy="0 0 0"/>
  <parent link="base_link"/>
  <child link="link1_1_1"/>
  <axis xyz="0.0 0.0 1.0"/>
  <limit lower="-3.141593" upper="3.141593" effort="150" velocity="3.15"/>
  <dynamics damping="10.0" friction="1.0"/>
</joint>

<joint name="joint2" type="revolute">
  <origin xyz="-0.017 -0.035 0.0375" rpy="0 0 0"/>
  <parent link="link1_1_1"/>
  <child link="link2_1_1"/>
  <axis xyz="1.0 0.0 -0.0"/>
  <limit lower="-1.308997" upper="1.570796" effort="150" velocity="3.15"/>
  <dynamics damping="10.0" friction="1.0"/>
</joint>

<joint name="joint3" type="revolute">
  <origin xyz="0.032 0.0 0.146" rpy="0 0 0"/>
  <parent link="link2_1_1"/>
  <child link="link3_1_1"/>
  <axis xyz="1.0 -0.0 -0.0"/>
  <limit lower="-1.570796" upper="1.570796" effort="150" velocity="3.15"/>
  <dynamics damping="10.0" friction="1.0"/>
</joint>

<joint name="joint4" type="revolute">
  <origin xyz="-0.017 -0.0175 0.052" rpy="0 0 0"/>
  <parent link="link3_1_1"/>
  <child link="link4_1_1"/>
  <axis xyz="0.0 -1.0 0.0"/>
  <limit lower="-3.14" upper="3.14" effort="150" velocity="3.15"/>
  <dynamics damping="10.0" friction="1.0"/>
</joint>

<joint name="joint5" type="revolute">
  <origin xyz="-0.0176 -0.1025 0.0" rpy="0 0 0"/>
  <parent link="link4_1_1"/>
  <child link="link5_1_1"/>
  <axis xyz="-1.0 -0.0 0.0"/>
  <limit lower="-1.570796" upper="1.570796" effort="150" velocity="3.15"/>
  <dynamics damping="10.0" friction="1.0"/>
</joint>

<joint name="joint6" type="revolute">
  <origin xyz="0.0186 -0.0605 0.0" rpy="0 0 0"/>
  <parent link="link5_1_1"/>
  <child link="link6_1_1"/>
  <axis xyz="0.0 1.0 -0.0"/>
  <limit lower="-3.14" upper="3.14" effort="150" velocity="3.15"/>
  <dynamics damping="10.0" friction="1.0"/>
</joint>

<!-- ROS2 Control 硬件接口 -->
<ros2_control name="GazeboSystem" type="system">
  <hardware>
    <plugin>gazebo_ros2_control/GazeboSystem</plugin>
  </hardware>
  
  <joint name="joint1">
    <command_interface name="position">
      <param name="min">-3.141593</param>
      <param name="max">3.141593</param>
    </command_interface>
    <state_interface name="position"/>
    <state_interface name="velocity"/>
  </joint>
  
  <joint name="joint2">
    <command_interface name="position">
      <param name="min">-1.308997</param>
      <param name="max">1.570796</param>
    </command_interface>
    <state_interface name="position"/>
    <state_interface name="velocity"/>
  </joint>
  
  <joint name="joint3">
    <command_interface name="position">
      <param name="min">-1.570796</param>
      <param name="max">1.570796</param>
    </command_interface>
    <state_interface name="position"/>
    <state_interface name="velocity"/>
  </joint>
  
  <joint name="joint4">
    <command_interface name="position">
      <param name="min">-3.14</param>
      <param name="max">3.14</param>
    </command_interface>
    <state_interface name="position"/>
    <state_interface name="velocity"/>
  </joint>
  
  <joint name="joint5">
    <command_interface name="position">
      <param name="min">-1.570796</param>
      <param name="max">1.570796</param>
    </command_interface>
    <state_interface name="position"/>
    <state_interface name="velocity"/>
  </joint>
  
  <joint name="joint6">
    <command_interface name="position">
      <param name="min">-3.14</param>
      <param name="max">3.14</param>
    </command_interface>
    <state_interface name="position"/>
    <state_interface name="velocity"/>
  </joint>
</ros2_control>

<!-- Gazebo ROS2 Control 插件 -->
<gazebo>
  <plugin filename="libgazebo_ros2_control.so" name="gazebo_ros2_control">
    <parameters>$(find dummy_moveit_config)/config/gazebo_controllers.yaml</parameters>
  </plugin>
</gazebo>

<!-- 为每个链接添加Gazebo材质属性和设置 -->
<gazebo reference="base_link">
  <material>Gazebo/Grey</material>
  <gravity>false</gravity>
</gazebo>

<gazebo reference="link1_1_1">
  <material>Gazebo/Grey</material>
  <gravity>false</gravity>
</gazebo>

<gazebo reference="link2_1_1">
  <material>Gazebo/Grey</material>
  <gravity>false</gravity>
</gazebo>

<gazebo reference="link3_1_1">
  <material>Gazebo/Grey</material>
  <gravity>false</gravity>
</gazebo>

<gazebo reference="link4_1_1">
  <material>Gazebo/Grey</material>
  <gravity>false</gravity>
</gazebo>

<gazebo reference="link5_1_1">
  <material>Gazebo/Grey</material>
  <gravity>false</gravity>
</gazebo>

<gazebo reference="link6_1_1">
  <material>Gazebo/Grey</material>
  <gravity>false</gravity>
</gazebo>

<!-- D435深度相机安装在J6末端 -->
<xacro:sensor_d435 parent="link6_1_1" name="d435" use_nominal_extrinsics="true">
  <origin xyz="0.00 -0.04 0.03" rpy="0 0 -1.5708"/>
</xacro:sensor_d435>

<!-- Gazebo D435相机插件 -->
<gazebo reference="d435_link">
  <sensor type="depth" name="d435_depth_sensor">
    <update_rate>30</update_rate>
    <camera>
      <horizontal_fov>1.211</horizontal_fov>
      <image>
        <width>640</width>
        <height>480</height>
        <format>R8G8B8</format>
      </image>
      <clip>
        <near>0.02</near>
        <far>10.0</far>
      </clip>
    </camera>
    <plugin name="d435_depth_driver" filename="libgazebo_ros_camera.so">
      <ros>
        <namespace>/d435</namespace>
        <remapping>~/image_raw:=depth/image_rect_raw</remapping>
        <remapping>~/camera_info:=depth/camera_info</remapping>
      </ros>
      <camera_name>d435</camera_name>
      <frame_name>d435_depth_optical_frame</frame_name>
      <hack_baseline>0.07</hack_baseline>
    </plugin>
  </sensor>
</gazebo>

<gazebo reference="d435_color_frame">
  <sensor type="camera" name="d435_color_sensor">
    <update_rate>30</update_rate>
    <camera>
      <horizontal_fov>1.211</horizontal_fov>
      <image>
        <width>640</width>
        <height>480</height>
        <format>R8G8B8</format>
      </image>
      <clip>
        <near>0.02</near>
        <far>10.0</far>
      </clip>
    </camera>
    <plugin name="d435_color_driver" filename="libgazebo_ros_camera.so">
      <ros>
        <namespace>/d435</namespace>
        <remapping>~/image_raw:=color/image_raw</remapping>
        <remapping>~/camera_info:=color/camera_info</remapping>
      </ros>
      <camera_name>d435</camera_name>
      <frame_name>d435_color_optical_frame</frame_name>
    </plugin>
  </sensor>
</gazebo>

</robot> 